class NegativeError extends Error {}
const add = (a: number, b: number) => {
  if (a < 0) {
    throw new NegativeError("a is negative");
  }
  return a + b;
};
describe("Simple Test Suite", () => {
  it("should pass a simple test", () => {
    expect(true).toBe(true);
  });
  test("1+1は2", () => {
    expect(1 + 1).toBe(2);
  });
});

describe("add", () => {
  it("1+1", () => {
    expect(add(1, 1)).toBe(2);
  });
  test("throw NegativeError", () => {
    expect(() => add(-1, 1)).toThrow(NegativeError);
  });
});

function wait(ms: number) {
  return new Promise((resolve) => {
    setTimeout(() => resolve(ms), ms);
  });
}

test("wait", async () => {
  const result = await wait(1000);
  expect(result).toBe(1000);
});
test("wait", () => {
  wait(1000).then((result) => {
    expect(result).toBe(1000);
  });
});

test("モック関数は実行された", () => {
  const mockFn = jest.fn();
  mockFn();
  expect(mockFn).toHaveBeenCalled();
});
